Workbook

Sheet כניסות
A3: Row Labels | B3: Count of תאריך כניסה.1 | C3: שם
A4: 8584744836 | B4: 3 | C4: =_xlfn.XLOOKUP(A4,'ללא כפולים'!C:C,'ללא כפולים'!B:B) -> aamoial | I4: ='מסכם '!D6 -> aamoial | J4: =COUNTIFS($B:$B,">2",$C:$C,I4) -> 3
A5: 1922570366 | B5: 2 | C5: =_xlfn.XLOOKUP(A5,'ללא כפולים'!C:C,'ללא כפולים'!B:B) -> tsiloni | I5: ='מסכם '!E6 -> hsalab | J5: =COUNTIFS($B:$B,">2",$C:$C,I5) -> 0
A6: 5974850932 | B6: 2 | C6: =_xlfn.XLOOKUP(A6,'ללא כפולים'!C:C,'ללא כפולים'!B:B) -> osayada | I6: ='מסכם '!F6 -> kshalev | J6: =COUNTIFS($B:$B,">2",$C:$C,I6) -> 3
A7: 4786906515 | B7: 3 | C7: =_xlfn.XLOOKUP(A7,'ללא כפולים'!C:C,'ללא כפולים'!B:B) -> kshalev | I7: ='מסכם '!G6 -> sappelba | J7: =COUNTIFS($B:$B,">2",$C:$C,I7) -> 2
A8: 2815456884 | B8: 3 | C8: =_xlfn.XLOOKUP(A8,'ללא כפולים'!C:C,'ללא כפולים'!B:B) -> #N/A | I8: ='מסכם '!H6 -> osayada | J8: =COUNTIFS($B:$B,">2",$C:$C,I8) -> 2
A9: 3048895920 | B9: 1 | C9: =_xlfn.XLOOKUP(A9,'ללא כפולים'!C:C,'ללא כפולים'!B:B) -> tsiloni | I9: ='מסכם '!I6 -> vbogache | J9: =COUNTIFS($B:$B,">2",$C:$C,I9) -> 0
A10: 2491668782 | B10: 2 | C10: =_xlfn.XLOOKUP(A10,'ללא כפולים'!C:C,'ללא כפולים'!B:B) -> tsiloni | I10: ='מסכם '!J6 -> ohabani | J10: =COUNTIFS($B:$B,">2",$C:$C,I10) -> 0
A11: 1050802174 | B11: 1 | C11: =_xlfn.XLOOKUP(A11,'ללא כפולים'!C:C,'ללא כפולים'!B:B) -> kshalev | I11: ='מסכם '!#REF! -> #REF! | J11: =COUNTIFS($B:$B,">2",$C:$C,I11) -> 0
A12: 3738160624 | B12: 1 | C12: =_xlfn.XLOOKUP(A12,'ללא כפולים'!C:C,'ללא כפולים'!B:B) -> sappelba | I12: ='מסכם '!K6 -> shpearl | J12: =COUNTIFS($B:$B,">2",$C:$C,I12) -> 1
A13: 4839141090 | B13: 1 | C13: =_xlfn.XLOOKUP(A13,'ללא כפולים'!C:C,'ללא כפולים'!B:B) -> kshalev | I13: ='מסכם '!L6 -> gborocho | J13: =COUNTIFS($B:$B,">2",$C:$C,I13) -> 1
A14: 9236088525 | B14: 1 | C14: =_xlfn.XLOOKUP(A14,'ללא כפולים'!C:C,'ללא כפולים'!B:B) -> #N/A | I14: ='מסכם '!M6 -> ifilosof | J14: =COUNTIFS($B:$B,">2",$C:$C,I14) -> 1
A15: 5274312562 | B15: 1 | C15: =_xlfn.XLOOKUP(A15,'ללא כפולים'!C:C,'ללא כפולים'!B:B) -> hsalab | I15: ='מסכם '!N6 -> lsharon | J15: =COUNTIFS($B:$B,">2",$C:$C,I15) -> 1
A16: 6999224024 | B16: 1 | C16: =_xlfn.XLOOKUP(A16,'ללא כפולים'!C:C,'ללא כפולים'!B:B) -> hsalab | I16: ='מסכם '!O6 -> 0 | J16: =COUNTIFS($B:$B,">2",$C:$C,I16) -> 0
A17: 1922777172 | B17: 1 | C17: =_xlfn.XLOOKUP(A17,'ללא כפולים'!C:C,'ללא כפולים'!B:B) -> osayada | J17: =COUNTIFS($B:$B,">2",$C:$C,I17) -> 0
A18: 3649589823 | B18: 1 | C18: =_xlfn.XLOOKUP(A18,'ללא כפולים'!C:C,'ללא כפולים'!B:B) -> lsharon
A19: 5272603711 | B19: 1 | C19: =_xlfn.XLOOKUP(A19,'ללא כפולים'!C:C,'ללא כפולים'!B:B) -> kshalev
A20: 3302727256 | B20: 3 | C20: =_xlfn.XLOOKUP(A20,'ללא כפולים'!C:C,'ללא כפולים'!B:B) -> kshalev
A21: 3048219646 | B21: 1 | C21: =_xlfn.XLOOKUP(A21,'ללא כפולים'!C:C,'ללא כפולים'!B:B) -> osayada
A22: 8223971066 | B22: 1 | C22: =_xlfn.XLOOKUP(A22,'ללא כפולים'!C:C,'ללא כפולים'!B:B) -> hsalab
A23: 3358746285 | B23: 2 | C23: =_xlfn.XLOOKUP(A23,'ללא כפולים'!C:C,'ללא כפולים'!B:B) -> lsharon
A24: 5370162501 | B24: 1 | C24: =_xlfn.XLOOKUP(A24,'ללא כפולים'!C:C,'ללא כפולים'!B:B) -> #N/A
A25: 8367677920 | B25: 1 | C25: =_xlfn.XLOOKUP(A25,'ללא כפולים'!C:C,'ללא כפולים'!B:B) -> lsharon
A26: 1285794274 | B26: 1 | C26: =_xlfn.XLOOKUP(A26,'ללא כפולים'!C:C,'ללא כפולים'!B:B) -> sappelba
A27: 8927770902 | B27: 2 | C27: =_xlfn.XLOOKUP(A27,'ללא כפולים'!C:C,'ללא כפולים'!B:B) -> aamoial
A28: 7247411780 | B28: 1 | C28: =_xlfn.XLOOKUP(A28,'ללא כפולים'!C:C,'ללא כפולים'!B:B) -> ifilosof
A29: 4681545061 | B29: 1 | C29: =_xlfn.XLOOKUP(A29,'ללא כפולים'!C:C,'ללא כפולים'!B:B) -> lsharon
... A379: Grand Total | B379: 454 | C379: =_xlfn.XLOOKUP(A379,'ללא כפולים'!C:C,'ללא כפולים'!B:B) -> #N/A
C380: =_xlfn.XLOOKUP(A380,'ללא כפולים'!C:C,'ללא כפולים'!B:B) -> #N/A
C381: =_xlfn.XLOOKUP(A381,'ללא כפולים'!C:C,'ללא כפולים'!B:B) -> #N/A
C382: =_xlfn.XLOOKUP(A382,'ללא כפולים'!C:C,'ללא כפולים'!B:B) -> #N/A
C383: =_xlfn.XLOOKUP(A383,'ללא כפולים'!C:C,'ללא כפולים'!B:B) -> #N/A
C384: =_xlfn.XLOOKUP(A384,'ללא כפולים'!C:C,'ללא כפולים'!B:B) -> #N/A
C385: =_xlfn.XLOOKUP(A385,'ללא כפולים'!C:C,'ללא כפולים'!B:B) -> #N/A
C386: =_xlfn.XLOOKUP(A386,'ללא כפולים'!C:C,'ללא כפולים'!B:B) -> #N/A
C387: =_xlfn.XLOOKUP(A387,'ללא כפולים'!C:C,'ללא כפולים'!B:B) -> #N/A
C388: =_xlfn.XLOOKUP(A388,'ללא כפולים'!C:C,'ללא כפולים'!B:B) -> #N/A
C389: =_xlfn.XLOOKUP(A389,'ללא כפולים'!C:C,'ללא כפולים'!B:B) -> #N/A
C390: =_xlfn.XLOOKUP(A390,'ללא כפולים'!C:C,'ללא כפולים'!B:B) -> #N/A
C391: =_xlfn.XLOOKUP(A391,'ללא כפולים'!C:C,'ללא כפולים'!B:B) -> #N/A
...

Sheet ללא כפולים
A1: Source.Name | B1: USER_CODE | C1: HAWB | D1: Step date | E1: Step name ENG | F1: Step name HEB | G1: STEP STATUS | H1: Hour | I1: POA
A2: נגיעות.xlsx | B2: aamoial | C2: 6691068635 | D2: 31/03/2024 | E2: TL5 | F2: נדרש אישור, ניתן לפטור ע"י קבלת תוספת חמישית | G2: Close | H2: 7 | I2: keep
A3: נגיעות.xlsx | B3: hsalab | C3: 2394229574 | D3: 31/03/2024 | E3: HLM | F3: אישור שירות המזון | G3: Active | H3: 7 | I3: keep
A4: נגיעות.xlsx | B4: hsalab | C4: 6484123166 | D4: 31/03/2024 | E4: TLA | F4: אישור תקן | G4: Pending | H4: 8 | I4: keep
A5: נגיעות.xlsx | B5: hsalab | C5: 4728357406 | D5: 31/03/2024 | E5: POA Missing | F5: חסר יפוי כח | G5: Pending | H5: 8 | I5: keep
A6: נגיעות.xlsx | B6: ifilosof | C6: 2396604254 | D6: 31/03/2024 | E6: NG | F6: הצהרה מהלקוח | G6: Active | H6: 8 | I6: keep
A7: נגיעות.xlsx | B7: hsalab | C7: 3287704560 | D7: 31/03/2024 | E7: IN | F7: נדרש חשבון ספק | G7: Pending | H7: 8 | I7: keep
A8: נגיעות.xlsx | B8: ifilosof | C8: 7247411780 | D8: 31/03/2024 | E8: CL | F8: אישור תקשורת | G8: Active | H8: 8 | I8: keep
A9: נגיעות.xlsx | B9: hsalab | C9: 4867884066 | D9: 31/03/2024 | E9: Importer Declaration Missing | F9: חסר תצהיר יבואן | G9: Pending | H9: 8 | I9: keep
A10: נגיעות.xlsx | B10: hsalab | C10: 7218843391 | D10: 31/03/2024 | E10: RV | F10: ערך אמיתי | G10: Close | H10: 8 | I10: keep
A11: נגיעות.xlsx | B11: hsalab | C11: 4909289906 | D11: 31/03/2024 | E11: 3PB | F11: 3PB | G11: Active | H11: 8 | I11: keep
A12: נגיעות.xlsx | B12: aamoial | C12: 1884116124 | D12: 31/03/2024 | E12: CL | F12: אישור תקשורת | G12: Pending | H12: 8 | I12: keep
A13: נגיעות.xlsx | B13: ifilosof | C13: 1884156492 | D13: 31/03/2024 | E13: HLM | F13: אישור שירות המזון | G13: Active | H13: 8 | I13: keep
... A850: נגיעות.xlsx | B850: ifilosof | C850: 3274264442 | D850: 31/03/2024 | E850: VALVE TLA | F850: תקן לשסתום | G850: Pending | H850: 17 | I850: keep

Sheet יעילות קוזי
J1: HOUR | K1: =C16 -> 31/03/2024 | L1: =D16 -> 0 | M1: =E16 -> 0 | N1: =F16 -> 0 | O1: =G16 -> 0 | P1: =H16 -> 0 | Q1: =I16 -> 0
J2: 7 | K2: =COUNTIFS($A:$A,$J$2,C:C,"<>") -> 2 | L2: =COUNTIFS($A:$A,$J$2,D:D,"<>") -> 0 | M2: =COUNTIFS($A:$A,$J$2,E:E,"<>") -> 0 | N2: =COUNTIFS($A:$A,$J$2,F:F,"<>") -> 0 | O2: =COUNTIFS($A:$A,$J$2,G:G,"<>") -> 0 | P2: =COUNTIFS($A:$A,$J$2,H:H,"<>") -> 0 | Q2: =COUNTIFS($A:$A,$J$2,I:I,"<>") -> 0
J3: 8 | K3: =COUNTIFS($A:$A,$J$3,C:C,"<>") -> 108 | L3: =COUNTIFS($A:$A,$J$3,D:D,"<>") -> 0 | M3: =COUNTIFS($A:$A,$J$3,E:E,"<>") -> 0 | N3: =COUNTIFS($A:$A,$J$3,F:F,"<>") -> 0 | O3: =COUNTIFS($A:$A,$J$3,G:G,"<>") -> 0 | P3: =COUNTIFS($A:$A,$J$3,H:H,"<>") -> 0 | Q3: =COUNTIFS($A:$A,$J$3,I:I,"<>") -> 0
J4: 9 | K4: =COUNTIFS($A:$A,$J$4,C:C,"<>") -> 144 | L4: =COUNTIFS($A:$A,$J$4,D:D,"<>") -> 0 | M4: =COUNTIFS($A:$A,$J$4,E:E,"<>") -> 0 | N4: =COUNTIFS($A:$A,$J$4,F:F,"<>") -> 0 | O4: =COUNTIFS($A:$A,$J$4,G:G,"<>") -> 0 | P4: =COUNTIFS($A:$A,$J$4,H:H,"<>") -> 0 | Q4: =COUNTIFS($A:$A,$J$4,I:I,"<>") -> 0
J5: 10 | K5: =COUNTIFS($A:$A,$J$5,C:C,"<>") -> 142 | L5: =COUNTIFS($A:$A,$J$5,D:D,"<>") -> 0 | M5: =COUNTIFS($A:$A,$J$5,E:E,"<>") -> 0 | N5: =COUNTIFS($A:$A,$J$5,F:F,"<>") -> 0 | O5: =COUNTIFS($A:$A,$J$5,G:G,"<>") -> 0 | P5: =COUNTIFS($A:$A,$J$5,H:H,"<>") -> 0 | Q5: =COUNTIFS($A:$A,$J$5,I:I,"<>") -> 0
J6: 11 | K6: =COUNTIFS($A:$A,$J$6,C:C,"<>") -> 185 | L6: =COUNTIFS($A:$A,$J$6,D:D,"<>") -> 0 | M6: =COUNTIFS($A:$A,$J$6,E:E,"<>") -> 0 | N6: =COUNTIFS($A:$A,$J$6,F:F,"<>") -> 0 | O6: =COUNTIFS($A:$A,$J$6,G:G,"<>") -> 0 | P6: =COUNTIFS($A:$A,$J$6,H:H,"<>") -> 0 | Q6: =COUNTIFS($A:$A,$J$6,I:I,"<>") -> 0
J7: 12 | K7: =COUNTIFS($A:$A,$J$7,C:C,"<>") -> 86 | L7: =COUNTIFS($A:$A,$J$7,D:D,"<>") -> 0 | M7: =COUNTIFS($A:$A,$J$7,E:E,"<>") -> 0 | N7: =COUNTIFS($A:$A,$J$7,F:F,"<>") -> 0 | O7: =COUNTIFS($A:$A,$J$7,G:G,"<>") -> 0 | P7: =COUNTIFS($A:$A,$J$7,H:H,"<>") -> 0 | Q7: =COUNTIFS($A:$A,$J$7,I:I,"<>") -> 0
J8: 13 | K8: =COUNTIFS($A:$A,$J$8,C:C,"<>") -> 135 | L8: =COUNTIFS($A:$A,$J$8,D:D,"<>") -> 0 | M8: =COUNTIFS($A:$A,$J$8,E:E,"<>") -> 0 | N8: =COUNTIFS($A:$A,$J$8,F:F,"<>") -> 0 | O8: =COUNTIFS($A:$A,$J$8,G:G,"<>") -> 0 | P8: =COUNTIFS($A:$A,$J$8,H:H,"<>") -> 0 | Q8: =COUNTIFS($A:$A,$J$8,I:I,"<>") -> 0
J9: 14 | K9: =COUNTIFS($A:$A,$J$9,C:C,"<>") -> 136 | L9: =COUNTIFS($A:$A,$J$9,D:D,"<>") -> 0 | M9: =COUNTIFS($A:$A,$J$9,E:E,"<>") -> 0 | N9: =COUNTIFS($A:$A,$J$9,F:F,"<>") -> 0 | O9: =COUNTIFS($A:$A,$J$9,G:G,"<>") -> 0 | P9: =COUNTIFS($A:$A,$J$9,H:H,"<>") -> 0 | Q9: =COUNTIFS($A:$A,$J$9,I:I,"<>") -> 0
J10: 15 | K10: =COUNTIFS($A:$A,$J$10,C:C,"<>") -> 127 | L10: =COUNTIFS($A:$A,$J$10,D:D,"<>") -> 0 | M10: =COUNTIFS($A:$A,$J$10,E:E,"<>") -> 0 | N10: =COUNTIFS($A:$A,$J$10,F:F,"<>") -> 0 | O10: =COUNTIFS($A:$A,$J$10,G:G,"<>") -> 0 | P10: =COUNTIFS($A:$A,$J$10,H:H,"<>") -> 0 | Q10: =COUNTIFS($A:$A,$J$10,I:I,"<>") -> 0
J11: 16 | K11: =COUNTIFS($A:$A,$J$11,C:C,"<>") -> 122 | L11: =COUNTIFS($A:$A,$J$11,D:D,"<>") -> 0 | M11: =COUNTIFS($A:$A,$J$11,E:E,"<>") -> 0 | N11: =COUNTIFS($A:$A,$J$11,F:F,"<>") -> 0 | O11: =COUNTIFS($A:$A,$J$11,G:G,"<>") -> 0 | P11: =COUNTIFS($A:$A,$J$11,H:H,"<>") -> 0 | Q11: =COUNTIFS($A:$A,$J$11,I:I,"<>") -> 0
P13: סה"כ | Q13: =SUM(K2:Q11) -> 1187
A15: Count of HAWB | C15: Step date
A16: Hour | B16: HAWB | C16: 31/03/2024
A17: 7 | B17: 6691068635 | C17: 1
A18: 7 | B18: 2394229574 | C18: 1
A19: 8 | B19: 6484123166 | C19: 1
A20: 8 | B20: 4728357406 | C20: 1
A21: 8 | B21: 2396604254 | C21: 1
A22: 8 | B22: 3287704560 | C22: 2
A23: 8 | B23: 7247411780 | C23: 1
A24: 8 | B24: 4867884066 | C24: 1
A25: 8 | B25: 7218843391 | C25: 1
A26: 8 | B26: 4909289906 | C26: 2
A27: 8 | B27: 1884116124 | C27: 1
A28: 8 | B28: 1884156492 | C28: 1
... A1211: 17 | B1211: 3274264442 | C1211: 1

Sheet דוח נגיעות
A1: Source.Name | B1: USER_CODE | C1: HAWB | D1: Step date | E1: Step name ENG | F1: Step name HEB | G1: STEP STATUS | H1: Hour | I1: POA
A2: נגיעות.xlsx | B2: aamoial | C2: 6691068635 | D2: 31/03/2024 | E2: TL5 | F2: נדרש אישור, ניתן לפטור ע"י קבלת תוספת חמישית | G2: Close | H2: 7 | I2: keep
A3: נגיעות.xlsx | B3: hsalab | C3: 2394229574 | D3: 31/03/2024 | E3: HLM | F3: אישור שירות המזון | G3: Active | H3: 7 | I3: keep
A4: נגיעות.xlsx | B4: hsalab | C4: 6484123166 | D4: 31/03/2024 | E4: TLA | F4: אישור תקן | G4: Pending | H4: 8 | I4: keep
A5: נגיעות.xlsx | B5: hsalab | C5: 4728357406 | D5: 31/03/2024 | E5: POA Missing | F5: חסר יפוי כח | G5: Pending | H5: 8 | I5: keep
A6: נגיעות.xlsx | B6: ifilosof | C6: 2396604254 | D6: 31/03/2024 | E6: NG | F6: הצהרה מהלקוח | G6: Active | H6: 8 | I6: keep
A7: נגיעות.xlsx | B7: hsalab | C7: 3287704560 | D7: 31/03/2024 | E7: IN | F7: נדרש חשבון ספק | G7: Pending | H7: 8 | I7: keep
A8: נגיעות.xlsx | B8: hsalab | C8: 3287704560 | D8: 31/03/2024 | E8: RTA | F8: אישור רשות שדות התעופה :רתא | G8: Pending | H8: 8 | I8: keep
A9: נגיעות.xlsx | B9: ifilosof | C9: 7247411780 | D9: 31/03/2024 | E9: CL | F9: אישור תקשורת | G9: Active | H9: 8 | I9: keep
A10: נגיעות.xlsx | B10: hsalab | C10: 4867884066 | D10: 31/03/2024 | E10: Importer Declaration Missing | F10: חסר תצהיר יבואן | G10: Pending | H10: 8 | I10: keep
A11: נגיעות.xlsx | B11: hsalab | C11: 7218843391 | D11: 31/03/2024 | E11: RV | F11: ערך אמיתי | G11: Close | H11: 8 | I11: keep
A12: נגיעות.xlsx | B12: hsalab | C12: 4909289906 | D12: 31/03/2024 | E12: 3PB | F12: 3PB | G12: Active | H12: 8 | I12: keep
A13: נגיעות.xlsx | B13: hsalab | C13: 4909289906 | D13: 31/03/2024 | E13: 3PB | F13: 3PB | G13: Active | H13: 8 | I13: keep
... A1554: נגיעות.xlsx | B1554: gborocho | C1554: 9490305333 | D1554: 31/03/2024 | E1554: TL5 | F1554: נדרש אישור, ניתן לפטור ע"י קבלת תוספת חמישית | G1554: Active | H1554: 17 | I1554: keep

Sheet מסכם 
C6: 31.3.24 | D6: aamoial | E6: hsalab | F6: kshalev | G6: sappelba | H6: osayada | I6: vbogache | J6: ohabani | K6: shpearl | L6: gborocho | M6: ifilosof | N6: lsharon
C7: יוניק תיקים | D7: =COUNTIF('ללא כפולים'!$B:$B,'מסכם '!D6) -> 142 | E7: =COUNTIF('ללא כפולים'!$B:$B,'מסכם '!E6) -> 102 | F7: =COUNTIF('ללא כפולים'!$B:$B,'מסכם '!F6) -> 112 | G7: =COUNTIF('ללא כפולים'!$B:$B,'מסכם '!G6) -> 84 | H7: =COUNTIF('ללא כפולים'!$B:$B,'מסכם '!H6) -> 93 | I7: =COUNTIF('ללא כפולים'!$B:$B,'מסכם '!I6) -> 0 | J7: =COUNTIF('ללא כפולים'!$B:$B,'מסכם '!J6) -> 0 | K7: =COUNTIF('ללא כפולים'!$B:$B,'מסכם '!K6) -> 55 | ... O7: =COUNTIF('ללא כפולים'!$B:$B,'מסכם '!O6) -> 0
C8: נגיעות | D8: =COUNTIF('דוח נגיעות'!$B:$B,'מסכם '!D6) -> 224 | E8: =COUNTIF('דוח נגיעות'!$B:$B,'מסכם '!E6) -> 216 | F8: =COUNTIF('דוח נגיעות'!$B:$B,'מסכם '!F6) -> 190 | G8: =COUNTIF('דוח נגיעות'!$B:$B,'מסכם '!G6) -> 182 | H8: =COUNTIF('דוח נגיעות'!$B:$B,'מסכם '!H6) -> 181 | I8: =COUNTIF('דוח נגיעות'!$B:$B,'מסכם '!I6) -> 0 | J8: =COUNTIF('דוח נגיעות'!$B:$B,'מסכם '!J6) -> 0 | K8: =COUNTIF('דוח נגיעות'!$B:$B,'מסכם '!K6) -> 105 | ... O8: =COUNTIF('דוח נגיעות'!$B:$B,'מסכם '!O6) -> 0
C9: פינגפונג | D9: =SUMIF(כניסות!$I:$I,'מסכם '!D6,כניסות!$J:$J) -> 3 | E9: =SUMIF(כניסות!$I:$I,'מסכם '!E6,כניסות!$J:$J) -> 0 | F9: =SUMIF(כניסות!$I:$I,'מסכם '!F6,כניסות!$J:$J) -> 3 | G9: =SUMIF(כניסות!$I:$I,'מסכם '!G6,כניסות!$J:$J) -> 2 | H9: =SUMIF(כניסות!$I:$I,'מסכם '!H6,כניסות!$J:$J) -> 2 | I9: =SUMIF(כניסות!$I:$I,'מסכם '!I6,כניסות!$J:$J) -> 0 | J9: =SUMIF(כניסות!$I:$I,'מסכם '!J6,כניסות!$J:$J) -> 0 | K9: =SUMIF(כניסות!$I:$I,'מסכם '!K6,כניסות!$J:$J) -> 1 | ... O9: =SUMIF(כניסות!$I:$I,'מסכם '!O6,כניסות!$J:$J) -> 0
C10: אחוז פינג פונג | D10: =D9/D7 -> 0.021126761 | E10: =E9/E7 -> 0 | F10: =F9/F7 -> 0.026785714 | G10: =G9/G7 -> 0.023809524 | H10: =H9/H7 -> 0.021505376 | I10: =I9/I7 -> #DIV/0! | J10: =J9/J7 -> #DIV/0! | K10: =K9/K7 -> 0.018181818 | ... O10: =O9/O7 -> #DIV/0!
C11: כמות טיפולים בשעה | D11: =D8/D12 -> 28 | E11: =E8/E12 -> 27 | F11: =F8/F12 -> 23.75 | G11: =G8/G12 -> 22.75 | H11: =H8/H12 -> 22.625 | I11: =I8/I12 -> #DIV/0! | J11: =J8/J12 -> 0 | K11: =K8/K12 -> 13.125 | ... O11: =O8/O12 -> #DIV/0!
C12: כמות שעות עבודה בפועל | D12: 8 | E12: 8 | F12: 8 | G12: 8 | H12: 8 | I12: 0 | J12: 8 | K12: 8 | L12: 8 | M12: 8 | N12: 8 | O12: 0
